[2022-07-26 02:35:11,307] {taskinstance.py:1179} INFO - Dependencies all met for <TaskInstance: GOOG_historic_data.load_historic_data_into_postgres manual__2022-07-26T02:34:02.109552+00:00 [queued]>
[2022-07-26 02:35:11,324] {taskinstance.py:1179} INFO - Dependencies all met for <TaskInstance: GOOG_historic_data.load_historic_data_into_postgres manual__2022-07-26T02:34:02.109552+00:00 [queued]>
[2022-07-26 02:35:11,325] {taskinstance.py:1376} INFO - 
--------------------------------------------------------------------------------
[2022-07-26 02:35:11,325] {taskinstance.py:1377} INFO - Starting attempt 2 of 2
[2022-07-26 02:35:11,325] {taskinstance.py:1378} INFO - 
--------------------------------------------------------------------------------
[2022-07-26 02:35:11,344] {taskinstance.py:1397} INFO - Executing <Task(PythonOperator): load_historic_data_into_postgres> on 2022-07-26 02:34:02.109552+00:00
[2022-07-26 02:35:11,350] {standard_task_runner.py:52} INFO - Started process 17263 to run task
[2022-07-26 02:35:11,353] {standard_task_runner.py:79} INFO - Running: ['***', 'tasks', 'run', 'GOOG_historic_data', 'load_historic_data_into_postgres', 'manual__2022-07-26T02:34:02.109552+00:00', '--job-id', '93', '--raw', '--subdir', 'DAGS_FOLDER/open_options.py', '--cfg-path', '/tmp/tmpc869cpun', '--error-file', '/tmp/tmphtng_5mn']
[2022-07-26 02:35:11,354] {standard_task_runner.py:80} INFO - Job 93: Subtask load_historic_data_into_postgres
[2022-07-26 02:35:11,474] {task_command.py:371} INFO - Running <TaskInstance: GOOG_historic_data.load_historic_data_into_postgres manual__2022-07-26T02:34:02.109552+00:00 [running]> on host 527e7914f635
[2022-07-26 02:35:11,630] {taskinstance.py:1591} INFO - Exporting the following env vars:
AIRFLOW_CTX_DAG_OWNER=vardhan
AIRFLOW_CTX_DAG_ID=GOOG_historic_data
AIRFLOW_CTX_TASK_ID=load_historic_data_into_postgres
AIRFLOW_CTX_EXECUTION_DATE=2022-07-26T02:34:02.109552+00:00
AIRFLOW_CTX_TRY_NUMBER=2
AIRFLOW_CTX_DAG_RUN_ID=manual__2022-07-26T02:34:02.109552+00:00
[2022-07-26 02:35:12,054] {base.py:68} INFO - Using connection ID 'postgres_optionsdata' for task execution.
[2022-07-26 02:35:12,060] {dbapi.py:231} INFO - Running statement: INSERT INTO historic_GOOG (symbol, date, high_price, low_price, open_price, close_price, total_volume) VALUES ("{'GOOG'}", 1654691040000, 116.95, 116.95, 116.95, 116.95, 4000) ON CONFLICT DO NOTHING, parameters: None
[2022-07-26 02:35:12,063] {taskinstance.py:1909} ERROR - Task failed with exception
Traceback (most recent call last):
  File "/home/airflow/.local/lib/python3.7/site-packages/airflow/operators/python.py", line 171, in execute
    return_value = self.execute_callable()
  File "/home/airflow/.local/lib/python3.7/site-packages/airflow/operators/python.py", line 189, in execute_callable
    return self.python_callable(*self.op_args, **self.op_kwargs)
  File "/opt/airflow/dags/open_options.py", line 337, in load_historic_data_into_postgres
    postgres_hook.run(query_insert % str(row))
  File "/home/airflow/.local/lib/python3.7/site-packages/airflow/hooks/dbapi.py", line 211, in run
    self._run_command(cur, sql_statement, parameters)
  File "/home/airflow/.local/lib/python3.7/site-packages/airflow/hooks/dbapi.py", line 235, in _run_command
    cur.execute(sql_statement)
psycopg2.errors.UndefinedColumn: column "{'GOOG'}" does not exist
LINE 1: ...e, open_price, close_price, total_volume) VALUES ("{'GOOG'}"...
                                                             ^

[2022-07-26 02:35:12,080] {taskinstance.py:1420} INFO - Marking task as FAILED. dag_id=GOOG_historic_data, task_id=load_historic_data_into_postgres, execution_date=20220726T023402, start_date=20220726T023511, end_date=20220726T023512
[2022-07-26 02:35:12,109] {standard_task_runner.py:97} ERROR - Failed to execute job 93 for task load_historic_data_into_postgres (column "{'GOOG'}" does not exist
LINE 1: ...e, open_price, close_price, total_volume) VALUES ("{'GOOG'}"...
                                                             ^
; 17263)
[2022-07-26 02:35:12,171] {local_task_job.py:156} INFO - Task exited with return code 1
[2022-07-26 02:35:12,280] {local_task_job.py:273} INFO - 0 downstream tasks scheduled from follow-on schedule check
