[2022-07-22 14:11:45,228] {taskinstance.py:1179} INFO - Dependencies all met for <TaskInstance: get_options_data_FB.create_table manual__2022-07-22T14:11:44.006315+00:00 [queued]>
[2022-07-22 14:11:45,249] {taskinstance.py:1179} INFO - Dependencies all met for <TaskInstance: get_options_data_FB.create_table manual__2022-07-22T14:11:44.006315+00:00 [queued]>
[2022-07-22 14:11:45,249] {taskinstance.py:1376} INFO - 
--------------------------------------------------------------------------------
[2022-07-22 14:11:45,249] {taskinstance.py:1377} INFO - Starting attempt 1 of 2
[2022-07-22 14:11:45,249] {taskinstance.py:1378} INFO - 
--------------------------------------------------------------------------------
[2022-07-22 14:11:45,272] {taskinstance.py:1397} INFO - Executing <Task(PythonOperator): create_table> on 2022-07-22 14:11:44.006315+00:00
[2022-07-22 14:11:45,277] {standard_task_runner.py:52} INFO - Started process 367 to run task
[2022-07-22 14:11:45,280] {standard_task_runner.py:79} INFO - Running: ['***', 'tasks', 'run', 'get_options_data_FB', 'create_table', 'manual__2022-07-22T14:11:44.006315+00:00', '--job-id', '4', '--raw', '--subdir', 'DAGS_FOLDER/open_options.py', '--cfg-path', '/tmp/tmpz8pfpif1', '--error-file', '/tmp/tmp5ahe9yvy']
[2022-07-22 14:11:45,281] {standard_task_runner.py:80} INFO - Job 4: Subtask create_table
[2022-07-22 14:11:45,352] {task_command.py:371} INFO - Running <TaskInstance: get_options_data_FB.create_table manual__2022-07-22T14:11:44.006315+00:00 [running]> on host 3e4d0946f42d
[2022-07-22 14:11:45,431] {taskinstance.py:1591} INFO - Exporting the following env vars:
AIRFLOW_CTX_DAG_OWNER=chrischow
AIRFLOW_CTX_DAG_ID=get_options_data_FB
AIRFLOW_CTX_TASK_ID=create_table
AIRFLOW_CTX_EXECUTION_DATE=2022-07-22T14:11:44.006315+00:00
AIRFLOW_CTX_TRY_NUMBER=1
AIRFLOW_CTX_DAG_RUN_ID=manual__2022-07-22T14:11:44.006315+00:00
[2022-07-22 14:11:45,447] {base.py:68} INFO - Using connection ID 'postgres_optionsdata' for task execution.
[2022-07-22 14:11:45,454] {taskinstance.py:1909} ERROR - Task failed with exception
Traceback (most recent call last):
  File "/home/airflow/.local/lib/python3.7/site-packages/airflow/operators/python.py", line 171, in execute
    return_value = self.execute_callable()
  File "/home/airflow/.local/lib/python3.7/site-packages/airflow/operators/python.py", line 189, in execute_callable
    return self.python_callable(*self.op_args, **self.op_kwargs)
  File "/opt/airflow/dags/open_options.py", line 68, in create_table
    """)
  File "/home/airflow/.local/lib/python3.7/site-packages/airflow/hooks/dbapi.py", line 204, in run
    with closing(self.get_conn()) as conn:
  File "/home/airflow/.local/lib/python3.7/site-packages/airflow/providers/postgres/hooks/postgres.py", line 113, in get_conn
    self.conn = psycopg2.connect(**conn_args)
  File "/home/airflow/.local/lib/python3.7/site-packages/psycopg2/__init__.py", line 122, in connect
    conn = _connect(dsn, connection_factory=connection_factory, **kwasync)
psycopg2.OperationalError: connection to server at "postgres" (172.19.0.2), port 5432 failed: FATAL:  password authentication failed for user "***"

[2022-07-22 14:11:45,468] {taskinstance.py:1420} INFO - Marking task as UP_FOR_RETRY. dag_id=get_options_data_FB, task_id=create_table, execution_date=20220722T141144, start_date=20220722T141145, end_date=20220722T141145
[2022-07-22 14:11:45,487] {standard_task_runner.py:97} ERROR - Failed to execute job 4 for task create_table (connection to server at "postgres" (172.19.0.2), port 5432 failed: FATAL:  password authentication failed for user "***"
; 367)
[2022-07-22 14:11:45,532] {local_task_job.py:156} INFO - Task exited with return code 1
[2022-07-22 14:11:45,608] {local_task_job.py:273} INFO - 0 downstream tasks scheduled from follow-on schedule check
