[2022-07-26 02:02:26,507] {taskinstance.py:1179} INFO - Dependencies all met for <TaskInstance: GOOG_historic_data.transform_historic_data manual__2022-07-26T02:02:22.343014+00:00 [queued]>
[2022-07-26 02:02:26,522] {taskinstance.py:1179} INFO - Dependencies all met for <TaskInstance: GOOG_historic_data.transform_historic_data manual__2022-07-26T02:02:22.343014+00:00 [queued]>
[2022-07-26 02:02:26,523] {taskinstance.py:1376} INFO - 
--------------------------------------------------------------------------------
[2022-07-26 02:02:26,523] {taskinstance.py:1377} INFO - Starting attempt 1 of 2
[2022-07-26 02:02:26,523] {taskinstance.py:1378} INFO - 
--------------------------------------------------------------------------------
[2022-07-26 02:02:26,539] {taskinstance.py:1397} INFO - Executing <Task(PythonOperator): transform_historic_data> on 2022-07-26 02:02:22.343014+00:00
[2022-07-26 02:02:26,544] {standard_task_runner.py:52} INFO - Started process 4409 to run task
[2022-07-26 02:02:26,546] {standard_task_runner.py:79} INFO - Running: ['***', 'tasks', 'run', 'GOOG_historic_data', 'transform_historic_data', 'manual__2022-07-26T02:02:22.343014+00:00', '--job-id', '61', '--raw', '--subdir', 'DAGS_FOLDER/open_options.py', '--cfg-path', '/tmp/tmpz9y4gsmp', '--error-file', '/tmp/tmp54pb82se']
[2022-07-26 02:02:26,547] {standard_task_runner.py:80} INFO - Job 61: Subtask transform_historic_data
[2022-07-26 02:02:26,609] {task_command.py:371} INFO - Running <TaskInstance: GOOG_historic_data.transform_historic_data manual__2022-07-26T02:02:22.343014+00:00 [running]> on host 527e7914f635
[2022-07-26 02:02:26,705] {taskinstance.py:1591} INFO - Exporting the following env vars:
AIRFLOW_CTX_DAG_OWNER=vardhan
AIRFLOW_CTX_DAG_ID=GOOG_historic_data
AIRFLOW_CTX_TASK_ID=transform_historic_data
AIRFLOW_CTX_EXECUTION_DATE=2022-07-26T02:02:22.343014+00:00
AIRFLOW_CTX_TRY_NUMBER=1
AIRFLOW_CTX_DAG_RUN_ID=manual__2022-07-26T02:02:22.343014+00:00
[2022-07-26 02:02:26,942] {taskinstance.py:1909} ERROR - Task failed with exception
Traceback (most recent call last):
  File "/home/airflow/.local/lib/python3.7/site-packages/airflow/operators/python.py", line 171, in execute
    return_value = self.execute_callable()
  File "/home/airflow/.local/lib/python3.7/site-packages/airflow/operators/python.py", line 189, in execute_callable
    return self.python_callable(*self.op_args, **self.op_kwargs)
  File "/opt/airflow/dags/open_options.py", line 179, in transform_historic_data
    for item in data['candles']:
KeyError: 'candles'
[2022-07-26 02:02:26,951] {taskinstance.py:1420} INFO - Marking task as UP_FOR_RETRY. dag_id=GOOG_historic_data, task_id=transform_historic_data, execution_date=20220726T020222, start_date=20220726T020226, end_date=20220726T020226
[2022-07-26 02:02:26,970] {standard_task_runner.py:97} ERROR - Failed to execute job 61 for task transform_historic_data ('candles'; 4409)
[2022-07-26 02:02:26,999] {local_task_job.py:156} INFO - Task exited with return code 1
[2022-07-26 02:02:27,096] {local_task_job.py:273} INFO - 0 downstream tasks scheduled from follow-on schedule check
