[2022-07-22 14:09:39,893] {taskinstance.py:1179} INFO - Dependencies all met for <TaskInstance: get_options_data_FB.create_table scheduled__2022-07-22T13:30:00+00:00 [queued]>
[2022-07-22 14:09:39,904] {taskinstance.py:1179} INFO - Dependencies all met for <TaskInstance: get_options_data_FB.create_table scheduled__2022-07-22T13:30:00+00:00 [queued]>
[2022-07-22 14:09:39,904] {taskinstance.py:1376} INFO - 
--------------------------------------------------------------------------------
[2022-07-22 14:09:39,905] {taskinstance.py:1377} INFO - Starting attempt 2 of 2
[2022-07-22 14:09:39,905] {taskinstance.py:1378} INFO - 
--------------------------------------------------------------------------------
[2022-07-22 14:09:39,925] {taskinstance.py:1397} INFO - Executing <Task(PythonOperator): create_table> on 2022-07-22 13:30:00+00:00
[2022-07-22 14:09:39,930] {standard_task_runner.py:52} INFO - Started process 766 to run task
[2022-07-22 14:09:39,933] {standard_task_runner.py:79} INFO - Running: ['***', 'tasks', 'run', 'get_options_data_FB', 'create_table', 'scheduled__2022-07-22T13:30:00+00:00', '--job-id', '8', '--raw', '--subdir', 'DAGS_FOLDER/open_options.py', '--cfg-path', '/tmp/tmphgav4g_o', '--error-file', '/tmp/tmpv7omn16r']
[2022-07-22 14:09:39,934] {standard_task_runner.py:80} INFO - Job 8: Subtask create_table
[2022-07-22 14:09:39,992] {task_command.py:371} INFO - Running <TaskInstance: get_options_data_FB.create_table scheduled__2022-07-22T13:30:00+00:00 [running]> on host 64ccb97fbb2c
[2022-07-22 14:09:40,103] {taskinstance.py:1591} INFO - Exporting the following env vars:
AIRFLOW_CTX_DAG_OWNER=chrischow
AIRFLOW_CTX_DAG_ID=get_options_data_FB
AIRFLOW_CTX_TASK_ID=create_table
AIRFLOW_CTX_EXECUTION_DATE=2022-07-22T13:30:00+00:00
AIRFLOW_CTX_TRY_NUMBER=2
AIRFLOW_CTX_DAG_RUN_ID=scheduled__2022-07-22T13:30:00+00:00
[2022-07-22 14:09:40,159] {taskinstance.py:1909} ERROR - Task failed with exception
Traceback (most recent call last):
  File "/home/airflow/.local/lib/python3.7/site-packages/airflow/operators/python.py", line 171, in execute
    return_value = self.execute_callable()
  File "/home/airflow/.local/lib/python3.7/site-packages/airflow/operators/python.py", line 189, in execute_callable
    return self.python_callable(*self.op_args, **self.op_kwargs)
  File "/opt/airflow/dags/open_options.py", line 68, in create_table
    """)
  File "/home/airflow/.local/lib/python3.7/site-packages/airflow/hooks/dbapi.py", line 204, in run
    with closing(self.get_conn()) as conn:
  File "/home/airflow/.local/lib/python3.7/site-packages/airflow/providers/postgres/hooks/postgres.py", line 86, in get_conn
    conn = deepcopy(self.connection or self.get_connection(conn_id))
  File "/home/airflow/.local/lib/python3.7/site-packages/airflow/hooks/base.py", line 67, in get_connection
    conn = Connection.get_connection_from_secrets(conn_id)
  File "/home/airflow/.local/lib/python3.7/site-packages/airflow/models/connection.py", line 430, in get_connection_from_secrets
    raise AirflowNotFoundException(f"The conn_id `{conn_id}` isn't defined")
airflow.exceptions.AirflowNotFoundException: The conn_id `postgres_optionsdata` isn't defined
[2022-07-22 14:09:40,168] {taskinstance.py:1420} INFO - Marking task as FAILED. dag_id=get_options_data_FB, task_id=create_table, execution_date=20220722T133000, start_date=20220722T140939, end_date=20220722T140940
[2022-07-22 14:09:40,196] {standard_task_runner.py:97} ERROR - Failed to execute job 8 for task create_table (The conn_id `postgres_optionsdata` isn't defined; 766)
[2022-07-22 14:09:40,225] {local_task_job.py:156} INFO - Task exited with return code 1
[2022-07-22 14:09:40,366] {local_task_job.py:273} INFO - 0 downstream tasks scheduled from follow-on schedule check
