[2022-07-22 14:08:38,742] {taskinstance.py:1179} INFO - Dependencies all met for <TaskInstance: get_options_data_FB.create_table manual__2022-07-22T14:08:36.817001+00:00 [queued]>
[2022-07-22 14:08:38,758] {taskinstance.py:1179} INFO - Dependencies all met for <TaskInstance: get_options_data_FB.create_table manual__2022-07-22T14:08:36.817001+00:00 [queued]>
[2022-07-22 14:08:38,758] {taskinstance.py:1376} INFO - 
--------------------------------------------------------------------------------
[2022-07-22 14:08:38,758] {taskinstance.py:1377} INFO - Starting attempt 1 of 2
[2022-07-22 14:08:38,759] {taskinstance.py:1378} INFO - 
--------------------------------------------------------------------------------
[2022-07-22 14:08:38,783] {taskinstance.py:1397} INFO - Executing <Task(PythonOperator): create_table> on 2022-07-22 14:08:36.817001+00:00
[2022-07-22 14:08:38,792] {standard_task_runner.py:52} INFO - Started process 366 to run task
[2022-07-22 14:08:38,796] {standard_task_runner.py:79} INFO - Running: ['***', 'tasks', 'run', 'get_options_data_FB', 'create_table', 'manual__2022-07-22T14:08:36.817001+00:00', '--job-id', '5', '--raw', '--subdir', 'DAGS_FOLDER/open_options.py', '--cfg-path', '/tmp/tmphe87hola', '--error-file', '/tmp/tmpf7cro3oy']
[2022-07-22 14:08:38,798] {standard_task_runner.py:80} INFO - Job 5: Subtask create_table
[2022-07-22 14:08:38,870] {task_command.py:371} INFO - Running <TaskInstance: get_options_data_FB.create_table manual__2022-07-22T14:08:36.817001+00:00 [running]> on host 64ccb97fbb2c
[2022-07-22 14:08:38,944] {taskinstance.py:1591} INFO - Exporting the following env vars:
AIRFLOW_CTX_DAG_OWNER=chrischow
AIRFLOW_CTX_DAG_ID=get_options_data_FB
AIRFLOW_CTX_TASK_ID=create_table
AIRFLOW_CTX_EXECUTION_DATE=2022-07-22T14:08:36.817001+00:00
AIRFLOW_CTX_TRY_NUMBER=1
AIRFLOW_CTX_DAG_RUN_ID=manual__2022-07-22T14:08:36.817001+00:00
[2022-07-22 14:08:38,966] {taskinstance.py:1909} ERROR - Task failed with exception
Traceback (most recent call last):
  File "/home/airflow/.local/lib/python3.7/site-packages/airflow/operators/python.py", line 171, in execute
    return_value = self.execute_callable()
  File "/home/airflow/.local/lib/python3.7/site-packages/airflow/operators/python.py", line 189, in execute_callable
    return self.python_callable(*self.op_args, **self.op_kwargs)
  File "/opt/airflow/dags/open_options.py", line 68, in create_table
    """)
  File "/home/airflow/.local/lib/python3.7/site-packages/airflow/hooks/dbapi.py", line 204, in run
    with closing(self.get_conn()) as conn:
  File "/home/airflow/.local/lib/python3.7/site-packages/airflow/providers/postgres/hooks/postgres.py", line 86, in get_conn
    conn = deepcopy(self.connection or self.get_connection(conn_id))
  File "/home/airflow/.local/lib/python3.7/site-packages/airflow/hooks/base.py", line 67, in get_connection
    conn = Connection.get_connection_from_secrets(conn_id)
  File "/home/airflow/.local/lib/python3.7/site-packages/airflow/models/connection.py", line 430, in get_connection_from_secrets
    raise AirflowNotFoundException(f"The conn_id `{conn_id}` isn't defined")
airflow.exceptions.AirflowNotFoundException: The conn_id `postgres_optionsdata` isn't defined
[2022-07-22 14:08:38,970] {taskinstance.py:1420} INFO - Marking task as UP_FOR_RETRY. dag_id=get_options_data_FB, task_id=create_table, execution_date=20220722T140836, start_date=20220722T140838, end_date=20220722T140838
[2022-07-22 14:08:38,984] {standard_task_runner.py:97} ERROR - Failed to execute job 5 for task create_table (The conn_id `postgres_optionsdata` isn't defined; 366)
[2022-07-22 14:08:39,008] {local_task_job.py:156} INFO - Task exited with return code 1
[2022-07-22 14:08:39,138] {local_task_job.py:273} INFO - 0 downstream tasks scheduled from follow-on schedule check
